Workbook

Sheet SUMMARY
B2: JAN V4 | L2: JAN V3
B3: Sum of Value | C3: Column Labels | L3: Sum of Value | M3: Column Labels
B4: SEGMENT | C4: CONFIRMED | D4: POYTR | E4: CONFIRMED-BGIPL | F4: POYTR-BGIPL | G4: INTRANSIT | H4: TOTAL | L4: SEGMENT | M4: CONFIRMED | N4: POYTR | O4: CONFIRMED-BGIPL | P4: POYTR-BGIPL | Q4: INTRANSIT | R4: TOTAL | S4: CAPACITY ISSUE | T4: TOTAL
B5: CRC | C5: 53261827 | D5: 4252600 | E5: 6984000 | H5: 64498427 | L5: CRC | M5: 43675677 | N5: 13149000 | O5: 6984000 | R5: 63808677 | T5: 65488557
B6: CRC-SP | C6: 1257897.6 | H6: 1257897.6 | L6: CRC-SP | M6: 1257897.6 | R6: 1257897.6 | T6: 1257897.6
B7: DEVICE | C7: 8219620 | H7: 8219620 | L7: DEVICE | M7: 7767020 | N7: 452600 | R7: 8219620 | T7: 8309584
B8: ED | C8: 33199964 | E8: 5711373.5 | G8: 2262950 | H8: 41174287 | L8: ED | M8: 31235594 | N8: 1973296 | O8: 5711373.5 | Q8: 2262950 | R8: 41183213 | S8: 964250 | T8: 41772129
B9: KERR | C9: 2773400 | H9: 2773400 | L9: KERR | M9: 1648400 | N9: 1125000 | R9: 2773400 | T9: 2773400
B10: NS | E10: 782269.44 | F10: 744000 | H10: 1526269.4 | L10: NS | O10: 782269.44 | P10: 744000 | R10: 1526269.4 | T10: 1526269.4
B11: R2 | C11: 42940496 | H11: 42940496 | L11: R2 | M11: 38163869 | N11: 9755300 | R11: 47919169 | S11: 895200 | T11: 47127852
B12: RSP | C12: 19768794 | G12: 7507224 | H12: 27276018 | L12: RSP | M12: 19067794 | N12: 1913161.7 | Q12: 7507224 | R12: 28488180 | T12: 29215234
B13: SVP Vials | C13: 29926243 | G13: 5330880 | H13: 35257123 | L13: SVP Vials | M13: 29926243 | Q13: 5330880 | R13: 35257123 | T13: 33789747
B14: TATA | E14: 16577550 | F14: 4875750 | H14: 21453300 | L14: TATA | O14: 8776350 | P14: 10726650 | R14: 19503000 | T14: 19503000
B15: NHC | E15: 6824812 | F15: 2480700 | H15: 9305512 | L15: NHC | O15: 2506540 | P15: 6798972 | R15: 9305512 | T15: 9305512
B16: TOTAL | C16: 1.9134824e+08 | D16: 4252600 | E16: 36880005 | F16: 8100450 | G16: 15101054 | H16: 2.5568235e+08 | L16: BEVCAP | P16: 367000 | R16: 367000 | T16: 367000
L17: TOTAL | M17: 1.7274249e+08 | N17: 28368358 | O17: 24760533 | P17: 18636622 | Q17: 15101054 | R17: 2.5960906e+08 | S17: 1859450 | T17: 2.6043618e+08
B18: CF DEC HC | C18: 16722775 | E18: CF DEC NHC | F18: 447646 | L18: CF DEC HC | M18: 16722775 | O18: CF DEC NHC | P18: 447646
C19: BUDGET HC | D19: ACTUAL HC | E19: BUDGET NHC | F19: ACTUAL NHC | G19: TOTAL BUDGET | H19: GAP | M19: BUDGET HC | N19: ACTUAL HC | O19: BUDGET NHC | P19: ACTUAL NHC | Q19: TOTAL BUDGET | R19: GAP
B20: SALES TARGET | C20: 245000000 | D20: =SUM(C5:F13)+C18+C23 -> 2.3054526e+08 | E20: 55000000 | F20: =SUM(E14:F15)+F18 -> 31206458 | G20: =C20+E20 -> 300000000 | H20: =D20+F20-G20 -> -38248282 | L20: SALES TARGET | M20: 245000000 | N20: 2.3205527e+08 | O20: 55000000 | P20: 29623158 | Q20: 300000000 | R20: -38321572
B21: BAIN | C21: =SUM(C5:D15)+C18 -> 2.1232362e+08 | E21: BGIPL | F21: =SUM(E5:F15) -> 44980455 | L21: BAIN | M21: 2.1783363e+08 | O21: BGIPL | P21: 43397155
B22: TOTAL | C22: =C21+F21 -> 2.5730407e+08 | L22: TOTAL | M22: 2.6123078e+08
B23: ADDITIONAL | C23: 4000000 | D23: LUPIN | L23: ADDITIONAL | M23: 4000000 | N23: LUPIN
B24: TAKE/PAY | L24: TAKE/PAY
B25: Grand total | C25: =SUM(C22:C24) -> 2.6130407e+08 | L25: Grand total | M25: 2.6523078e+08

Sheet MAIN
A1: SEG | B1: KAM | C1: CUSTOMER NAME SOLD TO | D1: CUSTOMER NAME SHIP TO | E1: MAT | F1: DESCRIPTION | G1: QTY | H1: PRICE | I1: VALUE | J1: STATUS | K1: STOCK | L1: SHI STATUS | M1: SO | N1: PO NO | O1: OR DT | P1: LN | Q1: RQ DT | R1: SKU STATUS | S1: MCD | T1: PACKING | U1: Q REL | V1: STERLIZATION | W1: DISPATCH DATE | X1: RESIN CODE | Y1: RESIN | Z1: RESIN QTY | AA1: MB CODE | AB1: MB | AC1: MB QTY
A2: CRC | B2: PRIYANK | C2: AJANTA PHARMA - DAHEJ- SEZ | D2: AJANTA PHARMA - DAHEJ- SEZ | E2: 50110012 | F2: CR-33MM HS123/020-(P-WHT)-1 | G2: 200000 | H2: 2.76 | I2: =G2*H2 -> 552000 | J2: CONFIRMED | L2: SHIPPED | M2: 25501225 | N2: 4100308171 | O2: 45957 | P2: 1 | Q2: 46011 | S2: 46033 | T2: 1 | U2: 1 | W2: =S2+T2+U2 -> 46035
A3: CRC | B3: PRIYANK | C3: AJANTA PHARMA - DAHEJ- SEZ | D3: AJANTA PHARMA - DAHEJ- SEZ | E3: 50110011 | F3: CR-38MM HS123/020-(P-WHT)-1 | G3: 50000 | H3: 2.87 | I3: =G3*H3 -> 143500 | J3: CONFIRMED | K3: 50000 | L3: SHIPPED | M3: 25501352 | N3: 4100310655 | O3: 45975 | P3: 1 | Q3: 45996 | R3: IN STOCK | S3: 46028 | T3: 1 | U3: 1 | W3: =S3+T3+U3 -> 46030
A4: CRC | B4: PRIYANK | C4: AJANTA PHARMA - DAHEJ- SEZ | D4: AJANTA PHARMA - DAHEJ- SEZ | E4: 50110011 | F4: CR-38MM HS123/020-(P-WHT)-1 | G4: 50000 | H4: 2.87 | I4: =G4*H4 -> 143500 | J4: CONFIRMED | K4: 20000 | L4: SHIPPED | M4: 25501352 | N4: 4100310655 | O4: 45975 | P4: 2 | Q4: 46037 | R4: IN STOCK | S4: 46028 | T4: 1 | U4: 1 | W4: =S4+T4+U4 -> 46030
A5: RSP | B5: RAM | C5: Medical and Cosmetic products | D5: Medical and Cosmetic products | E5: 50114671 | F5: B-10ML RSP White -18C(L)-GS | G5: 372000 | H5: 2.6145 | I5: =G5*H5 -> 972594 | J5: INTRANSIT | M5: 24880091 | N5: 5425000000129 | O5: 45712 | P5: 1.2 | Q5: 46022 | S5: 46040 | T5: 1 | U5: 1 | V5: 3 | W5: =S5+T5+U5+V5 -> 46045
A6: RSP | B6: RAM | C6: Medical and Cosmetic products | D6: Medical and Cosmetic products | E6: 50081670 | F6: C-TAMPSAFE RSP WHITE(H)NEW-GS | G6: 372000 | H6: 1.5583 | I6: =G6*H6 -> 579687.6 | J6: INTRANSIT | M6: 24880091 | N6: 5425000000129 | O6: 45712 | P6: 2.2 | Q6: 46022 | S6: 46040 | T6: 1 | U6: 1 | V6: 3 | W6: =S6+T6+U6+V6 -> 46045
A7: RSP | B7: RAM | C7: Medical and Cosmetic products | D7: Medical and Cosmetic products | E7: 50081938 | F7: N-OPEN RSP WHITE (L)-GS | G7: 372000 | H7: 0.7532 | I7: =G7*H7 -> 280190.4 | J7: INTRANSIT | M7: 24880091 | N7: 5425000000129 | O7: 45712 | P7: 3.2 | Q7: 46022 | S7: 46040 | T7: 1 | U7: 1 | V7: 3 | W7: =S7+T7+U7+V7 -> 46045
A8: R2 | B8: PRIYANK | C8: AMNEAL PHARMACEUTICALS PVT LTD | D8: AMNEAL PHARMACEUTICALS PVT LTD | E8: 50113858 | F8: C-TS RSP R22.0 PINK310239 E-GS | G8: 100000 | H8: 2.36 | I8: =G8*H8 -> 236000 | J8: CONFIRMED | M8: 25500034 | N8: OP-25000001 | O8: 45752 | P8: 1 | Q8: 46022 | R8: FROM STOCK | S8: 46032 | T8: 1 | U8: 1 | V8: 3 | W8: =S8+T8+U8+V8 -> 46037
A9: R2 | B9: MIHIR | C9: DifGen Pharmaceuticals Private | D9: STERIL GENE LIFE SCIENCES PVT | E9: 50092585 | F9: B-15ML RSP WHITE R2 (L)-ET | G9: 20250 | H9: 3.5 | I9: =G9*H9 -> 70875 | J9: CONFIRMED | M9: 25500324 | N9: 3085/OP | O9: 45807 | P9: 1 | Q9: 46022 | R9: FROM STOCK | S9: 46024 | T9: 1 | U9: 1 | V9: 3 | W9: =S9+T9+U9+V9 -> 46029
A10: R2 | B10: MIHIR | C10: DifGen Pharmaceuticals Private | D10: STERIL GENE LIFE SCIENCES PVT | E10: 50091673 | F10: B-10ML RSP WHITE R2 (L)-ET | G10: 6000 | H10: 3.3 | I10: =G10*H10 -> 19800 | J10: CONFIRMED | M10: 25500324 | N10: 3085/OP | O10: 45807 | P10: 2 | Q10: 46022 | R10: FROM STOCK | S10: 46024 | T10: 1 | U10: 1 | V10: 3 | W10: =S10+T10+U10+V10 -> 46029
A11: R2 | B11: MIHIR | C11: DifGen Pharmaceuticals Private | D11: STERIL GENE LIFE SCIENCES PVT | E11: 50113756 | F11: C-TS RSP R2 2.0 PINK 64C-ET | G11: 36000 | H11: 2.3 | I11: =G11*H11 -> 82800 | J11: CONFIRMED | M11: 25500324 | N11: 3085/OP | O11: 45807 | P11: 3 | Q11: 46022 | R11: FROM STOCK | S11: 46024 | T11: 1 | U11: 1 | V11: 3 | W11: =S11+T11+U11+V11 -> 46029
A12: R2 | B12: MIHIR | C12: DifGen Pharmaceuticals Private | D12: STERIL GENE LIFE SCIENCES PVT | E12: 50111596 | F12: N-OPEN RSP-60MCL WHT 24C(L)-ET | G12: 36000 | H12: 1.8 | I12: =G12*H12 -> 64800 | J12: CONFIRMED | M12: 25500324 | N12: 3085/OP | O12: 45807 | P12: 5 | Q12: 46022 | R12: FROM STOCK | S12: 46024 | T12: 1 | U12: 1 | V12: 3 | W12: =S12+T12+U12+V12 -> 46029
A13: CRC | B13: PRIYANK | C13: AJANTA PHARMA - DAHEJ- SEZ | D13: AJANTA PHARMA - DAHEJ- SEZ | E13: 50110011 | F13: CR-38MM HS123/020-(P-WHT)-1 | G13: 100000 | H13: 2.87 | I13: =G13*H13 -> 287000 | J13: CONFIRMED | K13: 80000 | M13: 25501487 | N13: 4100313076 | O13: 45995 | P13: 2 | Q13: 46032 | S13: 46028 | T13: 1 | U13: 1 | W13: =S13+T13+U13 -> 46030
A14: ED | B14: PRIYANK | C14: INDIANA OPHTHALMICS LLP | D14: INDIANA OPHTHALMICS LLP | E14: 50110679 | F14: B-10ML RG WHITE 16C (L)-GS | G14: 200000 | H14: 1.94 | I14: =G14*H14 -> 388000 | J14: CONFIRMED | L14: IN STERILIZATION | M14: 25500397 | N14: IPOP250510 | O14: 45819 | P14: 1 | Q14: 46022 | R14: PRODUCTION | S14: 46038 | T14: 1 | U14: 1 | V14: 3 | W14: =S14+T14+U14+V14 -> 46043
A15: ED | B15: PRIYANK | C15: INDIANA OPHTHALMICS LLP | D15: INDIANA OPHTHALMICS LLP | E15: 50081903 | F15: C-TAMPSAFE SS(R) WHITE(H)-GS | G15: 200000 | H15: 0.63 | I15: =G15*H15 -> 126000 | J15: CONFIRMED | L15: IN STERILIZATION | M15: 25500397 | N15: IPOP250510 | O15: 45819 | P15: 2 | Q15: 46022 | R15: FROM STOCK | S15: 46038 | T15: 1 | U15: 1 | V15: 3 | W15: =S15+T15+U15+V15 -> 46043
A16: ED | B16: PRIYANK | C16: INDIANA OPHTHALMICS LLP | D16: INDIANA OPHTHALMICS LLP | E16: 50099121 | F16: N-OPEN RG WHITE 64C (L)-GS | G16: 200000 | H16: 0.28 | I16: =G16*H16 -> 56000 | J16: CONFIRMED | L16: IN STERILIZATION | M16: 25500397 | N16: IPOP250510 | O16: 45819 | P16: 3 | Q16: 46022 | R16: FROM STOCK | S16: 46038 | T16: 1 | U16: 1 | V16: 3 | W16: =S16+T16+U16+V16 -> 46043
A17: ED | B17: PRIYANK | C17: INDIANA OPHTHALMICS LLP | D17: INDIANA OPHTHALMICS LLP | E17: 50110679 | F17: B-10ML RG WHITE 16C (L)-GS | G17: 200000 | H17: 1.94 | I17: =G17*H17 -> 388000 | J17: CONFIRMED | M17: 25500397 | N17: IPOP250510 | O17: 45819 | P17: 1 | Q17: 46022 | R17: PRODUCTION | S17: 46033 | T17: 1 | U17: 1 | V17: 3 | W17: 46044
A18: ED | B18: PRIYANK | C18: INDIANA OPHTHALMICS LLP | D18: INDIANA OPHTHALMICS LLP | E18: 50081903 | F18: C-TAMPSAFE SS(R) WHITE(H)-GS | G18: 300000 | H18: 0.63 | I18: =G18*H18 -> 189000 | J18: CONFIRMED | L18: IN STERILIZATION | M18: 25500397 | N18: IPOP250510 | O18: 45819 | P18: 2 | Q18: 46022 | R18: FROM STOCK | S18: 46033 | T18: 1 | U18: 1 | V18: 3 | W18: 46044
A19: ED | B19: PRIYANK | C19: INDIANA OPHTHALMICS LLP | D19: INDIANA OPHTHALMICS LLP | E19: 50099121 | F19: N-OPEN RG WHITE 64C (L)-GS | G19: 300000 | H19: 0.28 | I19: =G19*H19 -> 84000 | J19: CONFIRMED | L19: IN STERILIZATION | M19: 25500397 | N19: IPOP250510 | O19: 45819 | P19: 3 | Q19: 46022 | R19: FROM STOCK | S19: 46033 | T19: 1 | U19: 1 | V19: 3 | W19: 46044
A20: RSP | B20: MIHIR | C20: LN LABORATORIES PRIVATE LIMITE | D20: LN LABORATORIES PRIVATE LIMITE | E20: 50114671 | F20: B-10ML RSP White -18C(L)-GS | G20: 25350 | H20: 3.75 | I20: =G20*H20 -> 95062.5 | J20: CONFIRMED | L20: IN STERILIZATION | M20: 25500426 | N20: PO/25-26/ 032 | O20: 45822 | P20: 4 | Q20: 46022 | R20: FROM STOCK | S20: 46026 | T20: 1 | U20: 1 | V20: 3 | W20: =S20+T20+U20+V20 -> 46031
A21: RSP | B21: MIHIR | C21: LN LABORATORIES PRIVATE LIMITE | D21: LN LABORATORIES PRIVATE LIMITE | E21: 50081723 | F21: C-TAMPSAFE RSP WHITE (H)-GS | G21: 25350 | H21: 2.85 | I21: =G21*H21 -> 72247.5 | J21: CONFIRMED | L21: IN STERILIZATION | M21: 25500426 | N21: PO/25-26/ 032 | O21: 45822 | P21: 5 | Q21: 46022 | R21: FROM STOCK | S21: 46026 | T21: 1 | U21: 1 | V21: 3 | W21: =S21+T21+U21+V21 -> 46031
A22: RSP | B22: MIHIR | C22: LN LABORATORIES PRIVATE LIMITE | D22: LN LABORATORIES PRIVATE LIMITE | E22: 50113649 | F22: N-OPEN RSP NATURAL-64C(L)-GS | G22: 25350 | H22: 2 | I22: =G22*H22 -> 50700 | J22: CONFIRMED | L22: IN STERILIZATION | M22: 25500426 | N22: PO/25-26/ 032 | O22: 45822 | P22: 6 | Q22: 46022 | R22: FROM STOCK | S22: 46026 | T22: 1 | U22: 1 | V22: 3 | W22: =S22+T22+U22+V22 -> 46031
A23: ED | B23: MIHIR | C23: AUROLAB | D23: AUROLAB | E23: 50111528 | F23: B-10ML "I" WHITE-16C (L)-GS | G23: 299750 | H23: 2.05 | I23: =G23*H23 -> 614487.5 | J23: CONFIRMED | M23: 25500442 | N23: PO/25-26/1428 | O23: 45825 | P23: 4.1 | Q23: 45995 | R23: PRODUCTION | S23: 46039 | T23: 1 | U23: 1 | V23: 3 | W23: =S23+T23+U23+V23 -> 46044
A24: ED | B24: MIHIR | C24: AUROLAB | D24: AUROLAB | E24: 50081808 | F24: C-TAMPSAFE "I" WHITE (H)-GS | G24: 298850 | H24: 0.75 | I24: =G24*H24 -> 224137.5 | J24: CONFIRMED | M24: 25500442 | N24: PO/25-26/1428 | O24: 45825 | P24: 5.1 | Q24: 45995 | R24: PRODUCTION | S24: 46039 | T24: 1 | U24: 1 | V24: 3 | W24: =S24+T24+U24+V24 -> 46044
A25: ED | B25: MIHIR | C25: AUROLAB | D25: AUROLAB | E25: 50111939 | F25: N-OPEN "I" NAT NEW 48C (L)-GS | G25: 299850 | H25: 0.31 | I25: =G25*H25 -> 92953.5 | J25: CONFIRMED | M25: 25500442 | N25: PO/25-26/1428 | O25: 45825 | P25: 6.1 | Q25: 45995 | R25: PRODUCTION | S25: 46039 | T25: 1 | U25: 1 | V25: 3 | W25: =S25+T25+U25+V25 -> 46044
A26: ED | B26: MIHIR | C26: AUROLAB | D26: AUROLAB | E26: 50111528 | F26: B-10ML "I" WHITE-16C (L)-GS | G26: 500000 | H26: 2.05 | I26: =G26*H26 -> 1025000 | J26: CONFIRMED | M26: 25500442 | N26: PO/25-26/1428 | O26: 45825 | P26: 7 | Q26: 46026 | R26: PRODUCTION | S26: 46042 | T26: 1 | U26: 1 | V26: 3 | W26: =S26+T26+U26+V26 -> 46047
A27: ED | B27: MIHIR | C27: AUROLAB | D27: AUROLAB | E27: 50081808 | F27: C-TAMPSAFE "I" WHITE (H)-GS | G27: 500000 | H27: 0.75 | I27: =G27*H27 -> 375000 | J27: CONFIRMED | M27: 25500442 | N27: PO/25-26/1428 | O27: 45825 | P27: 8 | Q27: 46026 | R27: PRODUCTION | S27: 46042 | T27: 1 | U27: 1 | V27: 3 | W27: =S27+T27+U27+V27 -> 46047
A28: ED | B28: MIHIR | C28: AUROLAB | D28: AUROLAB | E28: 50111939 | F28: N-OPEN "I" NAT NEW 48C (L)-GS | G28: 500000 | H28: 0.31 | I28: =G28*H28 -> 155000 | J28: CONFIRMED | M28: 25500442 | N28: PO/25-26/1428 | O28: 45825 | P28: 9 | Q28: 46026 | R28: PRODUCTION | S28: 46042 | T28: 1 | U28: 1 | V28: 3 | W28: =S28+T28+U28+V28 -> 46047
A29: ED | B29: PRIYANK | C29: CADILA PHARMACEUTICALS LIMITED | D29: CADILA PHARMACEUTICALS LIMITED | E29: 50082077 | F29: N-BLOCK RG NATURAL (L)-GS | G29: 17800 | H29: 0.26 | I29: =G29*H29 -> 4628 | J29: CONFIRMED | M29: 25500528 | N29: 2500228758 | O29: 45839 | P29: 1.2 | Q29: 46022 | R29: PRODUCTION | S29: 46041 | T29: 1 | U29: 1 | V29: 3 | W29: =S29+T29+U29+V29 -> 46046
A30: ED | B30: PRIYANK | C30: INDIANA OPHTHALMICS LLP | D30: INDIANA OPHTHALMICS LLP | E30: 50082175 | F30: B-5ML RG WHITE (L)-GS | G30: 100000 | H30: 1.74 | I30: =G30*H30 -> 174000 | J30: CONFIRMED-BGIPL | L30: SHIPPED | M30: 25500132 | N30: IPOP250990 | O30: 45912 | P30: 1 | Q30: 45933 | R30: PRODUCTION | S30: 46024 | T30: 1 | U30: 1 | V30: 3 | W30: =S30+T30+U30+V30 -> 46029
A31: ED | B31: PRIYANK | C31: INDIANA OPHTHALMICS LLP | D31: INDIANA OPHTHALMICS LLP | E31: 50082175 | F31: B-5ML RG WHITE (L)-GS | G31: 100000 | H31: 1.74 | I31: =G31*H31 -> 174000 | J31: CONFIRMED-BGIPL | L31: SHIPPED | M31: 25500132 | N31: IPOP250990 | O31: 45912 | P31: 1 | Q31: 45933 | R31: PRODUCTION | S31: 46024 | T31: 1 | U31: 1 | V31: 3 | W31: =S31+T31+U31+V31 -> 46029
A32: ED | B32: PRIYANK | C32: INDIANA OPHTHALMICS LLP | D32: INDIANA OPHTHALMICS LLP | E32: 50099121 | F32: N-OPEN RG WHITE 64C (L)-GS | G32: 200000 | H32: 0.28 | I32: =G32*H32 -> 56000 | J32: CAPACITY ISSUE | L32: SHIPPED | M32: 25500659 | N32: IPOP250719 | O32: 45860 | P32: 2 | Q32: 46022 | R32: FROM STOCK | S32: 46024 | T32: 1 | U32: 1 | V32: 3 | W32: =S32+T32+U32+V32 -> 46029
A33: ED | B33: PRIYANK | C33: INDIANA OPHTHALMICS LLP | D33: INDIANA OPHTHALMICS LLP | E33: 50081903 | F33: C-TAMPSAFE SS(R) WHITE(H)-GS | G33: 200000 | H33: 0.63 | I33: =G33*H33 -> 126000 | J33: CAPACITY ISSUE | L33: SHIPPED | M33: 25500659 | N33: IPOP250719 | O33: 45860 | P33: 3 | Q33: 46022 | R33: FROM STOCK | S33: 46024 | T33: 1 | U33: 1 | V33: 3 | W33: =S33+T33+U33+V33 -> 46029
A34: R2 | B34: MIHIR | C34: PRONTGEN HEALTH REMEDIES PRIVA | D34: PRONTGEN HEALTH REMEDIES PRIVA | E34: 50114309 | F34: B-10ML RSP WHITE R2 16C (L)-NS | G34: 2000 | H34: 3.6 | I34: =G34*H34 -> 7200 | J34: CONFIRMED | M34: 25500663 | N34: PHRPL/2025-26/063 | O34: 45860 | P34: 1 | Q34: 46022 | R34: FROM STOCK | S34: 46032 | T34: 1 | U34: 1 | V34: 3 | W34: =S34+T34+U34+V34 -> 46037
A35: R2 | B35: MIHIR | C35: PRONTGEN HEALTH REMEDIES PRIVA | D35: PRONTGEN HEALTH REMEDIES PRIVA | E35: 50113737 | F35: C-TS RSP R2 2.0 WHT 64C (H)-NS | G35: 2000 | H35: 2.85 | I35: =G35*H35 -> 5700 | J35: CONFIRMED | M35: 25500663 | N35: PHRPL/2025-26/063 | O35: 45860 | P35: 2 | Q35: 46022 | R35: FROM STOCK | S35: 46032 | T35: 1 | U35: 1 | V35: 3 | W35: =S35+T35+U35+V35 -> 46037
A36: R2 | B36: MIHIR | C36: PRONTGEN HEALTH REMEDIES PRIVA | D36: PRONTGEN HEALTH REMEDIES PRIVA | E36: 50114340 | F36: N-OPEN RSP WHITE 64C(L)-NS | G36: 2000 | H36: 1.85 | I36: =G36*H36 -> 3700 | J36: CONFIRMED | M36: 25500663 | N36: PHRPL/2025-26/063 | O36: 45860 | P36: 3 | Q36: 46022 | R36: FROM STOCK | S36: 46032 | T36: 1 | U36: 1 | V36: 3 | W36: =S36+T36+U36+V36 -> 46037
A37: ED | B37: PRIYANK | C37: INDIANA OPHTHALMICS LLP | D37: INDIANA OPHTHALMICS LLP | E37: 50082166 | F37: B-15ML RG WHITE (L)-GS | G37: 100000 | H37: 2.04 | I37: =G37*H37 -> 204000 | J37: CAPACITY ISSUE | M37: 25501566 | N37: IPOP251517 | O37: 46006 | P37: 1 | Q37: 46037 | R37: PRODUCTION | S37: 46049 | T37: 1 | U37: 1 | V37: 3 | W37: =S37+T37+U37+V37 -> 46054
A38: ED | B38: PRIYANK | C38: INDIANA OPHTHALMICS LLP | D38: INDIANA OPHTHALMICS LLP | E38: 50082175 | F38: B-5ML RG WHITE (L)-GS | G38: 98970 | H38: 1.74 | I38: =G38*H38 -> 172207.8 | J38: CONFIRMED-BGIPL | M38: 25500067 | N38: IPOP250508 | O38: 45819 | P38: 3.1 | Q38: 45961 | R38: PRODUCTION | S38: 46026 | T38: 1 | U38: 1 | V38: 3 | W38: =S38+T38+U38+V38 -> 46031
A39: ED | B39: PRIYANK | C39: INDIANA OPHTHALMICS LLP | D39: INDIANA OPHTHALMICS LLP | E39: 50099121 | F39: N-OPEN RG WHITE 64C (L)-GS | G39: 199360 | H39: 0.28 | I39: =G39*H39 -> 55820.8 | J39: CONFIRMED | L39: IN STERILIZATION | M39: 25500717 | N39: IPOP250752 | O39: 45867 | P39: 1.4 | Q39: 46022 | R39: FROM STOCK | S39: 46026 | T39: 1 | U39: 1 | V39: 3 | W39: =S39+T39+U39+V39 -> 46031
A40: ED | B40: PRIYANK | C40: INDIANA OPHTHALMICS LLP | D40: INDIANA OPHTHALMICS LLP | E40: 50081903 | F40: C-TAMPSAFE SS(R) WHITE(H)-GS | G40: 198890 | H40: 0.63 | I40: =G40*H40 -> 125300.7 | J40: CONFIRMED | L40: IN STERILIZATION | M40: 25500717 | N40: IPOP250752 | O40: 45867 | P40: 2.4 | Q40: 46022 | R40: FROM STOCK | S40: 46026 | T40: 1 | U40: 1 | V40: 3 | W40: =S40+T40+U40+V40 -> 46031
...

Sheet Sales loss
B1: SALES LOSS
B2: CUSTOMER | C2: PART CODE | D2: DESCRIPTION | E2: QTY | F2: PRICE | G2: VALUE | H2: REMARKS
B3: INDOCO REMEDIES LTD | C3: 50093242 | D3: B-5ML RSP R2 NAT. 1810E NEW-ET | E3: =400000+144000 -> 544000 | F3: 3.52 | G3: =E3*F3 -> 1914880 | H3: 1.We don’t have capacity in Peenya to run the product with IBM mold, 2.IMBM product to be validated and approval required from customer 3.We have free capacity in Sira to run the product but need management approval
B4: INDOCO REMEDIES LTD | C4: 50096946 | D4: B-10ML RSP NAT R2 1810E (L)-ET | E4: =84000+96000 -> 180000 | F4: 4.14 | G4: =E4*F4 -> 745200
B5: INDOCO REMEDIES LTD | C5: 50106297 | D5: C-TS RSP R2 2.0 WHT 1905(H)-ET | E5: =396000+288000 -> 684000 | F5: 1.86 | G5: =E5*F5 -> 1272240 | H5: Need to provide samples with 64c mold to customer for approval
B6: INDOCO REMEDIES LTD | C6: 50081841 | D6: N-OPEN RSP NATURAL(L)-ET | E6: =396000+288000 -> 684000 | F6: 1.39 | G6: =E6*F6 -> 950760
D7: TOTAL VALUE | G7: =SUM(G3:G6) -> 4883080

Sheet FORECAST
B1: 45839 | C1: 45870 | D1: 45901 | E1: 45931 | F1: 45962 | G1: 45992 | H1: 46023 | I1: 46054 | J1: 46082 | K1: 46113 | L1: 46143 | M1: 46174 | P1: 45839 | Q1: 45870 | R1: 45901 | S1: 45931 | T1: 45962 | U1: 45992 | V1: 46023 | W1: 46054 | X1: 46082 | Y1: 46113 | Z1: 46143 | AA1: 46174 | AF1: 45839 | AG1: 45870 | AH1: 45901 | AI1: 45931 | AJ1: 45962 | AK1: 45992 | AL1: 46023 | AM1: 46054 | AN1: 46082 | AO1: 46113 | AP1: 46143 | AQ1: 46174 | AT1: 45839 | AU1: 45870 | AV1: 45901 | AW1: 45931 | AX1: 45962 | AY1: 45992 | AZ1: 46023 | BA1: 46054 | BB1: 46082 | BC1: 46113 | BD1: 46143 | BE1: 46174
B3: Bud Jul 25 | C3: Bud Aug 25 | D3: Bud Sep 25 | E3: Bud Oct 25 | F3: Bud Nov 25 | G3: Bud Dec 25 | H3: Bud Jan 26 | I3: Bud Feb 26 | J3: Bud Mar 26 | K3: Bud Apr 26 | L3: Bud May 26 | M3: Bud Jun 26 | N3: Bud Total 26 | P3: Act Jul 25 | Q3: Act Aug 25 | R3: Act Sep 25 | S3: Act Oct 25 | T3: Act Nov 25 | U3: Fcst Dec 25 | V3: Fcst Jan 26 | W3: Fcst Feb 26 | X3: Fcst Mar 26 | Y3: Fcst Apr 26 | Z3: Fcst May 26 | AA3: Fcst Jun 26 | AB3: Fcst Total 26 | AF3: Bud Jul 25 | AG3: Bud Aug 25 | AH3: Bud Sep 25 | AI3: Bud Oct 25 | AJ3: Bud Nov 25 | AK3: Bud Dec 25 | AL3: Bud Jan 26 | AM3: Bud Feb 26 | AN3: Bud Mar 26 | AO3: Bud Apr 26 | AP3: Bud May 26 | AQ3: Bud Jun 26 | AR3: Bud Total 26 | AT3: Act Jul 25 | AU3: Act Aug 25 | AV3: Act Sep 25 | AW3: Act Oct 25 | AX3: Act Nov 25 | AY3: Fcst Dec 25 | AZ3: Fcst Jan 26 | BA3: Fcst Feb 26 | BB3: Fcst Mar 26 | BC3: Fcst Apr 26 | BD3: Fcst May 26 | BE3: Fcst Jun 26 | BF3: Fcst Total 26
A4: Sales volume (KGS) | B4: =342120-13000 -> 329120 | C4: =361917-13000 -> 348917 | D4: =343104-13000 -> 330104 | E4: =355252-26000 -> 329252 | F4: =361792-26000 -> 335792 | G4: =396116-39000 -> 357116 | H4: =366031+13000 -> 379031 | I4: 364292 | J4: 382949 | K4: =375548+39000 -> 414548 | L4: =376710+39000 -> 415710 | M4: =386606+39000 -> 425606 | N4: =SUM(B4:M4) -> 4412437 | P4: 339892 | Q4: 357435 | R4: 315046 | S4: 319147 | T4: 367995.54 | U4: 328649 | V4: =U4/U17*V17 -> 304521.91 | W4: =V4/V17*W17 -> 307537.46 | X4: =W4/W17*X17 -> 311205.08 | Y4: =X4/X17*Y17 -> 325262.07 | Z4: =Y4/Y17*Z17 -> 330337.68 | AA4: =Z4/Z17*AA17 -> 325410.25 | AB4: =SUM(P4:AA4) -> 3932439 | AE4: Sales volume (KGS) | AF4: 195364 | AG4: 195923 | AH4: 177828 | AI4: =175878+33644 -> 209522 | AJ4: =190889+33644 -> 224533 | AK4: =190762+33644 -> 224406 | AL4: 287373 | AM4: =391879-(33644*3) -> 290947 | AN4: 283933 | AO4: 280021 | AP4: 306411 | AQ4: 281289 | AR4: =SUM(AF4:AQ4) -> 2957550 | AT4: 89682 | AU4: 86164 | AV4: 122149 | AW4: 114917 | AX4: 111351.91 | AY4: 148526 | AZ4: 215805.36 | BA4: 256149.89 | BB4: 277250.66 | BC4: 248102.81 | BD4: 262559.5 | BE4: 236418.45 | BF4: =SUM(AT4:BE4) -> 2169076.6
A5: Sales revenue | B5: =B4/1000 -> 329.12 | C5: =C4/1000 -> 348.917 | D5: =D4/1000 -> 330.104 | AE5: Sales revenue | AF5: =AF4/1000 -> 195.364 | AG5: =AG4/1000 -> 195.923 | AH5: =AH4/1000 -> 177.828 | AZ5: 319223.3 | BA5: 293592.45 | BB5: 301980.58 | BC5: 271782.52 | BD5: 271782.52 | BE5: 271782.52
A6: CRC | B6: 57676948 | C6: 61600157 | D6: 62519348 | E6: 61475586 | F6: 60343942 | G6: 71806191 | H6: 62129642 | I6: 60947917 | J6: 72324734 | K6: 64219817 | L6: 60041533 | M6: 73495086 | N6: =SUM(B6:M6) -> 768580901 | P6: 52863219 | Q6: 64966500 | R6: 41308657 | S6: 46784166 | T6: 65290550 | U6: 51443529 | V6: =62129642-2000000 -> 60129642 | W6: 60947917 | X6: =72324734-5000000-7000000 -> 60324734 | Y6: =64219817-4000000 -> 60219817 | Z6: 60041533 | AA6: =73495086-11000000 -> 62495086 | AB6: =SUM(P6:AA6) -> 6.8681535e+08 | AE6: CRC | AF6: 9331200 | AG6: 9331200 | AH6: 11923200 | AI6: 9504000 | AJ6: 9625681.2 | AK6: 9480961.5 | AL6: 12960000 | AM6: 10080007 | AN6: 10368000 | AO6: 9331200 | AP6: 9331200 | AQ6: 9331200 | AR6: =SUM(AF6:AQ6) -> 120597850 | AT6: 11474496 | AU6: 6912000 | AV6: 5529600 | AW6: 7642260 | AX6: 7680600 | AY6: 6873420 | AZ6: 10960000 | BA6: 10080007 | BB6: 10368000 | BC6: 9331200 | BD6: 9331200 | BE6: 9331200 | BF6: =SUM(AT6:BE6) -> 1.0551398e+08
A7: RSP | B7: 68012754 | C7: 72669960 | D7: 61841661 | E7: 60950039 | F7: 70209024 | G7: 70499802 | H7: 87588922 | I7: 89821497 | J7: 82152481 | K7: 1.0455779e+08 | L7: 1.1405182e+08 | M7: 1.0249544e+08 | N7: =SUM(B7:M7) -> 9.848512e+08 | P7: 60514671 | Q7: 56529739 | R7: 75842386 | S7: 75702355 | T7: 65603467 | U7: 62072568 | V7: =87588922.32-15000000+3000000 -> 75588922 | W7: =89821496.88-17000000+3000000 -> 75821497 | X7: =82152480.96-10000000+3000000 -> 75152481 | Y7: =104557791.6-25000000 -> 79557792 | Z7: =114051824.64-35000000 -> 79051825 | AA7: =102495443.04-25000000+2000000 -> 79495443 | AB7: =SUM(P7:AA7) -> 8.6093315e+08 | AE7: RSP | AF7: 0 | AG7: 0 | AH7: 0 | AI7: 0 | AJ7: 0 | AK7: 0 | AL7: 0 | AM7: 0 | AN7: 0 | AO7: 0 | AP7: 0 | AQ7: 0 | AR7: =SUM(AF7:AQ7) -> 0 | AT7: 0 | AU7: 0 | AV7: 0 | AW7: 0 | AX7: 0 | AY7: 0 | AZ7: 0 | BA7: 0 | BB7: 0 | BC7: 0 | BD7: 0 | BE7: 0 | BF7: =SUM(AT7:BE7) -> 0
A8: ED | B8: 26449405 | C8: 28260540 | D8: 24049535 | E8: 23702793 | F8: 27303509 | G8: 27416589 | H8: 34062359 | I8: 34930582 | J8: 31948187 | K8: 40661363 | L8: 44353487 | M8: 39859339 | N8: =SUM(B8:M8) -> 3.8299769e+08 | P8: 35920809 | Q8: 33584846 | R8: 33044513 | S8: 29891524 | T8: 32487036 | U8: 33877835 | V8: 34062359 | W8: 34930582 | X8: =31948187.04+4000000 -> 35948187 | Y8: 40661363 | Z8: 44353487 | AA8: 39859339 | AB8: =SUM(P8:AA8) -> 4.2862188e+08 | AE8: ED | AF8: 5557416.5 | AG8: 4924499 | AH8: 4924499 | AI8: 7259974.8 | AJ8: 5887185.6 | AK8: 5950754.5 | AL8: 6113596.2 | AM8: 5236202.2 | AN8: 5684657.5 | AO8: 6614434.8 | AP8: 6601462.5 | AQ8: 6478710.1 | AR8: =SUM(AF8:AQ8) -> 71233393 | AT8: 3516269.4 | AU8: 4549656 | AV8: 3019941.2 | AW8: 1854285.6 | AX8: 2929637.4 | AY8: 5420299.7 | AZ8: 6113596.2 | BA8: 5236202.2 | BB8: 5684657.5 | BC8: 6614434.8 | BD8: 6601462.5 | BE8: 6478710.1 | BF8: =SUM(AT8:BE8) -> 58019153
A9: Vials | B9: 28357946 | C9: 34540963 | D9: 30139486 | E9: 29616718 | F9: 28039443 | G9: 24978486 | H9: 29273883 | I9: 22168269 | J9: 27500953 | K9: 29083366 | L9: 29233013 | M9: 28691779 | N9: =SUM(B9:M9) -> 341624305 | P9: 36949434 | Q9: 31174964 | R9: 28542802 | S9: 33839255 | T9: 28707310 | U9: 29522648 | V9: =29273883+1000000 -> 30273883 | W9: =22168269+9000000 -> 31168269 | X9: =27500953+4000000 -> 31500953 | Y9: =29083366+3000000 -> 32083366 | Z9: =29233013+3000000 -> 32233013 | AA9: =28691779+4000000 -> 32691779 | AB9: =SUM(P9:AA9) -> 3.7868768e+08 | AE9: Vials | AF9: 0 | AG9: 0 | AH9: 0 | AI9: 0 | AJ9: 0 | AK9: 0 | AL9: 0 | AM9: 0 | AN9: 0 | AO9: 0 | AP9: 0 | AQ9: 0 | AR9: =SUM(AF9:AQ9) -> 0 | AT9: 0 | AU9: 0 | AV9: 0 | AW9: 0 | AX9: 0 | AY9: 0 | AZ9: 0 | BA9: 0 | BB9: 0 | BC9: 3000000 | BD9: 3000000 | BE9: 4000000 | BF9: =SUM(AT9:BE9) -> 10000000
A10: Nebuliser | B10: 0 | C10: 0 | D10: 0 | E10: 0 | F10: 0 | G10: 0 | H10: 0 | I10: 0 | J10: 0 | K10: 0 | L10: 0 | M10: 0 | N10: =SUM(B10:M10) -> 0 | P10: 0 | Q10: 0 | R10: 0 | S10: 0 | T10: 0 | U10: 0 | V10: 0 | W10: 0 | X10: 0 | Y10: 0 | Z10: 0 | AA10: 0 | AB10: =SUM(P10:AA10) -> 0 | AE10: Nebuliser | AF10: 0 | AG10: 0 | AH10: 0 | AI10: 0 | AJ10: 0 | AK10: 0 | AL10: 0 | AM10: 0 | AN10: 0 | AO10: 0 | AP10: 0 | AQ10: 0 | AR10: =SUM(AF10:AQ10) -> 0 | AT10: 0 | AU10: 0 | AV10: 0 | AW10: 0 | AX10: 0 | AY10: 0 | AZ10: 0 | BA10: 0 | BB10: 0 | BC10: 0 | BD10: 0 | BE10: 0 | BF10: =SUM(AT10:BE10) -> 0
A11: Nasal Spray | B11: 0 | C11: 0 | D11: 0 | E11: 0 | F11: 0 | G11: 0 | H11: 0 | I11: 0 | J11: 0 | K11: 0 | L11: 0 | M11: 0 | N11: =SUM(B11:M11) -> 0 | P11: 0 | Q11: 0 | R11: 0 | S11: 0 | T11: 0 | U11: 0 | V11: 0 | W11: 0 | X11: 0 | Y11: 0 | Z11: 0 | AA11: 0 | AB11: =SUM(P11:AA11) -> 0 | AE11: Nasal Spray | AF11: 0 | AG11: 0 | AH11: 0 | AI11: 0 | AJ11: 0 | AK11: 0 | AL11: 0 | AM11: 0 | AN11: 0 | AO11: 0 | AP11: 0 | AQ11: 0 | AR11: =SUM(AF11:AQ11) -> 0 | AT11: 805000 | AU11: 377000 | AV11: 0 | AW11: 226620 | AX11: 873000 | AY11: 754000 | AZ11: 0 | BA11: 0 | BB11: 0 | BC11: 0 | BD11: 0 | BE11: 0 | BF11: =SUM(AT11:BE11) -> 3035620
A12: N-OP | B12: 0 | C12: 0 | D12: 0 | E12: 0 | F12: 0 | G12: 0 | H12: 0 | I12: 0 | J12: 0 | K12: 0 | L12: 0 | M12: 0 | N12: =SUM(B12:M12) -> 0 | P12: 0 | Q12: 0 | R12: 0 | S12: 0 | T12: 0 | U12: 0 | V12: 0 | W12: 0 | X12: 0 | Y12: 0 | Z12: 0 | AA12: 0 | AB12: =SUM(P12:AA12) -> 0 | AE12: N-OP | AF12: 0 | AG12: 0 | AH12: 0 | AI12: 0 | AJ12: 0 | AK12: 0 | AL12: 0 | AM12: 0 | AN12: 0 | AO12: 0 | AP12: 0 | AQ12: 0 | AR12: =SUM(AF12:AQ12) -> 0 | AT12: 0 | AU12: 0 | AV12: 0 | AW12: 0 | AX12: 0 | AY12: 0 | AZ12: 0 | BA12: 0 | BB12: 0 | BC12: 0 | BD12: 0 | BE12: 0 | BF12: =SUM(AT12:BE12) -> 0
A13: Devices | B13: 7867464 | C13: 3087704 | D13: 3532329 | E13: 12442751 | F13: 10330793 | G13: 24671873 | H13: 12923068 | I13: 10732751 | J13: 24209290 | K13: 14242751 | L13: 14430793 | M13: 17329293 | N13: =SUM(B13:M13) -> 155800860 | P13: 8948216.2 | Q13: 15502170 | R13: 8727527.5 | S13: 793839.2 | T13: 8603583.6 | U13: 19695084 | V13: =12923068-(65000*135) -> 4148068 | W13: =10732751-(65000*135)+1500000 -> 3457751 | X13: =24209290-(115000*135)-3000000 -> 5684290 | Y13: =14242751-(65000*135) -> 5467751 | Z13: =14430793-(65000*135) -> 5655793 | AA13: =17329293-(115000*135)+1650000 -> 3454293 | AB13: =SUM(P13:AA13) -> 90138366 | AE13: Devices | AF13: 0 | AG13: 0 | AH13: 0 | AI13: 0 | AJ13: 0 | AK13: 0 | AL13: 0 | AM13: 0 | AN13: 0 | AO13: 0 | AP13: 0 | AQ13: 0 | AR13: =SUM(AF13:AQ13) -> 0 | AT13: 0 | AU13: 0 | AV13: 0 | AW13: 0 | AX13: 0 | AY13: 0 | AZ13: 0 | BA13: 0 | BB13: 0 | BC13: 0 | BD13: 0 | BE13: 0 | BF13: =SUM(AT13:BE13) -> 0
A14: Non-healthcare | B14: 0 | C14: 0 | D14: 0 | E14: 0 | F14: 0 | G14: 0 | H14: 0 | I14: 0 | J14: 0 | K14: 0 | L14: 0 | M14: 0 | N14: =SUM(B14:M14) -> 0 | P14: 0 | Q14: 0 | R14: 0 | S14: 0 | T14: 0 | U14: 23728568 | V14: 0 | W14: 0 | X14: 0 | Y14: 0 | Z14: 0 | AA14: 0 | AB14: =SUM(P14:AA14) -> 23728568 | AE14: Non-healthcare | AF14: 35917575 | AG14: 38855707 | AH14: 33544841 | AI14: =29341020.19+8000000 -> 37341020 | AJ14: =35151342.47+8000000 -> 43151342 | AK14: =34697749.58+8000000 -> 42697750 | AL14: 55573988 | AM14: =82936074.89-24000000 -> 58936075 | AN14: 57343448 | AO14: 56673172 | AP14: 65097133 | AQ14: 57892508 | AR14: =SUM(AF14:AQ14) -> 5.8302456e+08 | AT14: 14260058 | AU14: 19982390 | AV14: 29862031 | AW14: 23434031 | AX14: 18866263 | AY14: 29783622 | AZ14: 45810958 | BA14: 59575665 | BB14: 65130583 | BC14: 53581237 | BD14: 57747133 | BE14: 49222508 | BF14: =SUM(AT14:BE14) -> 4.6725648e+08
A15: Freight recovered from customers | B15: 1957001 | C15: 2079608 | D15: 1891698 | E15: 1954115 | F15: 2037679 | G15: 2277234 | H15: 2350092 | I15: 2272360 | J15: 2475423 | K15: 2630645 | L15: 2727793 | M15: 2725301 | N15: =SUM(B15:M15) -> 27378949 | P15: 870597 | Q15: 1403195.6 | R15: 1236930 | S15: 10202154 | T15: 2013568.4 | U15: 2577805.7 | V15: 2350092 | W15: 2272360 | X15: 2475423 | Y15: 2630645 | Z15: 2727793 | AA15: 2725301 | AB15: =SUM(P15:AA15) -> 33485865 | AE15: Freight recovered from customers | AF15: =ROUND(SUM(AF6:AF14)*1.75%,0) -> 889108 | AG15: =ROUND(SUM(AG6:AG14)*1.75%,0) -> 929450 | AH15: =ROUND(SUM(AH6:AH14)*1.75%,0) -> 881869 | AI15: =ROUND(SUM(AI6:AI14)*1.75%,0) -> 946837 | AJ15: =ROUND(SUM(AJ6:AJ14)*1.75%,0) -> 1026624 | AK15: =ROUND(SUM(AK6:AK14)*1.75%,0) -> 1017266 | AL15: =ROUND(SUM(AL6:AL14)*1.75%,0) -> 1306333 | AM15: =ROUND(SUM(AM6:AM14)*1.75%,0) -> 1299415 | ... AQ15: =ROUND(SUM(AQ6:AQ14)*1.75%,0) -> 1289792 | AR15: =SUM(AF15:AQ15) -> 13559976 | AT15: 598160 | AU15: 652320 | AV15: 1219315 | AW15: 1169230 | AX15: 777800 | AY15: 1347430 | AZ15: 1306333 | BA15: 1299415 | BB15: 1284432 | BC15: 1270829 | BD15: 1418021 | BE15: 1289792 | BF15: =SUM(AT15:BE15) -> 13633077
A17: Gross Revenue | B17: =SUM(B6:B15) -> 190321518 | C17: =SUM(C6:C15) -> 202238932 | D17: =SUM(D6:D15) -> 183974057 | E17: =SUM(E6:E15) -> 190142002 | F17: =SUM(F6:F15) -> 198264390 | G17: =SUM(G6:G15) -> 221650175 | H17: =SUM(H6:H15) -> 228327966 | I17: =SUM(I6:I15) -> 220873376 | ... N17: =SUM(N6:N15) -> 2661233903 | P17: 1.9606695e+08 | Q17: 2.0316141e+08 | R17: 1.8870282e+08 | S17: 1.9721329e+08 | T17: =SUM(T6:T15) -> 2.0270551e+08 | U17: =SUM(U6:U15) -> 2.2291804e+08 | V17: =SUM(V6:V15) -> 206552966 | W17: =SUM(W6:W15) -> 208598376 | X17: =SUM(X6:X15) -> 2.1108607e+08 | Y17: =SUM(Y6:Y15) -> 220620734 | Z17: =SUM(Z6:Z15) -> 224063444 | AA17: =SUM(AA6:AA15) -> 2.2072124e+08 | AB17: =SUM(AB6:AB15) -> 2.5024108e+09 | AE17: Gross Revenue | AF17: =SUM(AF6:AF15) -> 51695299 | AG17: =SUM(AG6:AG15) -> 54040856 | AH17: =SUM(AH6:AH15) -> 51274409 | AI17: =SUM(AI6:AI15) -> 55051832 | AJ17: =SUM(AJ6:AJ15) -> 59690833 | AK17: =SUM(AK6:AK15) -> 59146732 | AL17: =SUM(AL6:AL15) -> 75953918 | AM17: =SUM(AM6:AM15) -> 75551699 | ... AR17: =SUM(AR6:AR15) -> 7.8841578e+08 | AT17: 30653983 | AU17: 32473366 | AV17: 39630887 | AW17: 34326426 | AX17: =SUM(AX6:AX15) -> 31127300 | AY17: =SUM(AY6:AY15) -> 44178772 | AZ17: 64190888 | BA17: 76191289 | BB17: 82467673 | BC17: 73797700 | BD17: 78097817 | BE17: 70322211 | BF17: =SUM(BF6:BF15) -> 6.5745831e+08
C23: AOP 2026 | I23: AOP 2026 | O23: AOP 2026 | U23: AOP 2026
C24: 46048 | I24: 46079 | O24: 46107 | U24: Q4
B25: Customers | C25: Qty | D25: Value | E25: Kgs | I25: Sum of Feb Unitss | J25: Sum of Feb | K25: Sum of Feb Kgss | O25: Sum of Mar Unitss | P25: Sum of Mar | Q25: Sum of Mar Kgss | U25: Total units | V25: Total Rev | W25: Total Tns
B26: BDF | C26: 1000000 | D26: 2500000 | E26: 5000 | I26: 2000000 | J26: 5000000 | K26: 10000 | O26: 2000000 | P26: 5000000 | Q26: 10000 | U26: =C26+I26+O26 -> 5000000 | V26: =D26+J26+P26 -> 12500000 | W26: =E26+K26+Q26 -> 25000
B27: Beverages | C27: 30000000 | D27: 10800000 | E27: 60000 | I27: 30000000 | J27: 10800000 | K27: 60000 | O27: 30000000 | P27: 10800000 | Q27: 60000 | U27: =C27+I27+O27 -> 90000000 | V27: =D27+J27+P27 -> 32400000 | W27: =E27+K27+Q27 -> 180000
B28: Dabur | C28: 885250 | D28: 3550965.1 | E28: 6250.25 | I28: 743750 | J28: 3013791.6 | K28: 5145.25 | O28: 670000 | P28: 2733457.9 | Q28: 4573 | U28: =C28+I28+O28 -> 2299000 | V28: =D28+J28+P28 -> 9298214.6 | W28: =E28+K28+Q28 -> 15968.5
B29: J&J/JNTL/Kenvue | C29: 2526000 | D29: 1540860 | E29: 5809.8 | I29: 3234000 | J29: 1972740 | K29: 7438.2 | O29: 4392000 | P29: 2707992.1 | Q29: 10101.6 | U29: =C29+I29+O29 -> 10152000 | V29: =D29+J29+P29 -> 6221592.1 | W29: =E29+K29+Q29 -> 23349.6
B30: Reckitt Benckiser | C30: 2000000 | D30: 3339133.3 | E30: 24600 | I30: 2000000 | J30: 3339133.3 | K30: 24600 | O30: 2000000 | P30: 3339133.3 | Q30: 24600 | U30: =C30+I30+O30 -> 6000000 | V30: =D30+J30+P30 -> 10017400 | W30: =E30+K30+Q30 -> 73800
B31: Tata | C31: 31629000 | D31: 33843030 | E31: 142330.5 | I31: 32533095 | J31: 34810412 | K31: 146398.93 | O31: 30619500 | P31: 32762865 | Q31: 137787.75 | U31: =C31+I31+O31 -> 94781595 | V31: =D31+J31+P31 -> 1.0141631e+08 | W31: =E31+K31+Q31 -> 426517.18
B32: Anything Additional | U32: =C32+I32+O32 -> 0 | V32: =D32+J32+P32 -> 0 | W32: =E32+K32+Q32 -> 0
B33: Grand Total | C33: =SUM(C26:C32) -> 68040250 | D33: =SUM(D26:D32) -> 55573988 | E33: =SUM(E26:E32) -> 243990.55 | I33: =SUM(I26:I32) -> 70510845 | J33: =SUM(J26:J32) -> 58936077 | K33: =SUM(K26:K32) -> 253582.38 | O33: =SUM(O26:O32) -> 69681500 | P33: =SUM(P26:P32) -> 57343448 | Q33: =SUM(Q26:Q32) -> 247062.35 | U33: =C33+I33+O33 -> 208232595 | V33: =D33+J33+P33 -> 1.7185351e+08 | W33: =E33+K33+Q33 -> 744635.28
C35: Sales Budget 2026 | I35: Sales Budget 2026 | O35: Sales Budget 2026 | U35: Sales Budget 2026
C36: 46048 | I36: 46079 | O36: 46107 | U36: Q4
B37: Customers | C37: Qty | D37: Value | E37: Kgs | I37: Sum of Feb Unitss | J37: Sum of Feb | K37: Sum of Feb Kgss | O37: Sum of Mar Unitss | P37: Sum of Mar | Q37: Sum of Mar Kgss | U37: Total units | V37: Total Rev | W37: Total Tns
B38: BDF | C38: 1000000 | D38: 2500000 | E38: 5000 | I38: 2000000 | J38: 5000000 | K38: 10000 | O38: 2000000 | P38: 5000000 | Q38: 10000 | U38: =C38+I38+O38 -> 5000000 | V38: =D38+J38+P38 -> 12500000 | W38: =E38+K38+Q38 -> 25000
B39: Beverages | C39: 30000000 | D39: 10800000 | E39: 60000 | I39: 30000000 | J39: 10800000 | K39: 60000 | O39: 30000000 | P39: 10800000 | Q39: 60000 | U39: =C39+I39+O39 -> 90000000 | V39: =D39+J39+P39 -> 32400000 | W39: =E39+K39+Q39 -> 180000
B40: Dabur | C40: 885250 | D40: 3550965.1 | E40: 6250.25 | I40: 743750 | J40: 3013791.6 | K40: 5145.25 | O40: 670000 | P40: 2733457.9 | Q40: 4573 | U40: =C40+I40+O40 -> 2299000 | V40: =D40+J40+P40 -> 9298214.6 | W40: =E40+K40+Q40 -> 15968.5
B41: J&J/JNTL/Kenvue | C41: 2526000 | D41: 1540860 | E41: 5809.8 | I41: 3234000 | J41: 1972740 | K41: 7438.2 | O41: 4392000 | P41: 2707992.1 | Q41: 10101.6 | U41: =C41+I41+O41 -> 10152000 | V41: =D41+J41+P41 -> 6221592.1 | W41: =E41+K41+Q41 -> 23349.6
B42: Reckitt Benckiser | C42: 2000000 | D42: 3339133.3 | E42: 24600 | I42: 2000000 | J42: 3339133.3 | K42: 24600 | O42: 2000000 | P42: 3339133.3 | Q42: 24600 | U42: =C42+I42+O42 -> 6000000 | V42: =D42+J42+P42 -> 10017400 | W42: =E42+K42+Q42 -> 73800
B43: Tata | C43: 31629000 | D43: =D31*C43/C31 -> 33843030 | E43: =C43*E31/C31 -> 142330.5 | I43: 54963000 | J43: =J31*I43/I31 -> 58810410 | K43: =I43*K31/I31 -> 247333.5 | O43: 41609250 | P43: =P31*O43/O31 -> 44521898 | Q43: =O43*Q31/O31 -> 187241.62 | U43: =C43+I43+O43 -> 128201250 | V43: =D43+J43+P43 -> 1.3717534e+08 | W43: =E43+K43+Q43 -> 576905.62
B44: Anything Additional | U44: =C44+I44+O44 -> 0 | V44: =D44+J44+P44 -> 0 | W44: =E44+K44+Q44 -> 0
B45: Grand Total | C45: =SUM(C38:C44) -> 68040250 | D45: =SUM(D38:D44) -> 55573988 | E45: =SUM(E38:E44) -> 243990.55 | I45: =SUM(I38:I44) -> 92940750 | J45: =SUM(J38:J44) -> 82936075 | K45: =SUM(K38:K44) -> 354516.95 | O45: =SUM(O38:O44) -> 80671250 | P45: =SUM(P38:P44) -> 69102481 | Q45: =SUM(Q38:Q44) -> 296516.22 | U45: =C45+I45+O45 -> 241652250 | V45: =D45+J45+P45 -> 2.0761254e+08 | W45: =E45+K45+Q45 -> 895023.72
C47: Updated Forecast 2026 | I47: Updated Forecast 2026 | O47: Updated Forecast 2026 | U47: Updated Forecast 2026
C48: 46048 | I48: 46079 | O48: 46107 | U48: Q4
B49: Customers | C49: Qty | D49: Value | E49: Kgs | I49: Sum of Feb Unitss | J49: Sum of Feb | K49: Sum of Feb Kgss | O49: Sum of Mar Unitss | P49: Sum of Mar | Q49: Sum of Mar Kgss | U49: Total units | V49: Total Rev | W49: Total Tns
...

Sheet APPASAMY DATES
B2: CODE | C2: DESCRIPTION | D2: QTY | E2: TENTATIVE DISPATCH DATE
B3: 50111525 | C3: B-10ML "I"O.GRN91151-16C(L)-GS | D3: 2,00,000 | E3: 45663
B4: 50082373 | C4: C-TAMP SAFE"I" O.GREEN-GS | D4: 2,00,000 | E4: 45663
B5: 50111939 | C5: N-OPEN "I" NAT NEW 48C (L)-GS | D5: 2,00,000 | E5: 45663
B6: 50110683 | C6: B-10ML RG O.GREEN 16C (L)-GS | D6: 3,00,000 | E6: 46028
B7: 50081930 | C7: C-DOUBLESAFE NX O.GREEN (H)-GS | D7: 3,00,000 | E7: 46028
B8: 50082077 | C8: N-BLOCK RG NATURAL (L)-GS | D8: 3,00,000 | E8: 46028
B9: 50102394 | C9: B-10ML "I" WHITE (L-J)-GS | D9: 1,00,000 | E9: 46028
B10: 50081808 | C10: C-TAMPSAFE "I" WHITE (H)-GS | D10: 1,00,000 | E10: 46028
B11: 50101632 | C11: N-OPEN "I" NATURAL NEW(L-J)-GS | D11: 1,00,000 | E11: 46028
B12: 50102394 | C12: B-5ML "I" WHITE (L-J)-GS | D12: 5,00,000 | E12: 45669
B13: 50081808 | C13: C-TAMPSAFE "I" WHITE (H)-GS | D13: 5,00,000 | E13: 45669
B14: 50101632 | C14: N-OPEN "I" NATURAL NEW(L-J)-GS | D14: 5,00,000 | E14: 45669

Sheet MASTER
A1: PRIMARY CODE | B1: PRIMARY DESCRIPTION | C1: SECONDARY CODE | D1: SECONDARY DESCRIPTION | E1: RESIN CODE | F1: RESIN | G1: RESIN QTY | H1: MB CODE | I1: MB | J1: MB QTY | L1: PRIMARY CODE | M1: PRIMARY DESCRIPTION | N1: SECONDARY CODE | O1: SECONDARY DESCRIPTION | P1: RESIN | Q1: RESIN QTY | R1: MB | S1: MB QTY | U1: Material Code | V1: Material Description | W1: Component Item Number | X1: Material Description2 | Y1: RESIN CODE | Z1: RESIN
A2: 50081410 | B2: N-OPEN RG NATURAL 64C (L-F)-GS | C2: 50081409 | D2: N-OPEN RG NATURAL 64C (L-F)-NS | E2: 50082198 | F2: LDPE: RELENE 22FF002 | G2: 0.597 | L2: 50081416 | M2: N-OPEN NBSR DT ASSY WHITE-NS | N2: 50082098 | O2: N-OPEN NBSR WHITE (L) | U2: 50081429 | V2: CR-38MM VIOLET .035FSM-1 BLK | W2: 50081994 | X2: 38MM OUTER CAPS VIOLET (2612C) | Y2: =VLOOKUP(W2,Sheet2!A:D,3,0) -> 50082181 | Z2: =VLOOKUP(W2,Sheet2!A:D,4,0) -> PPHP: COPYLENE CH120LN
A3: 50081411 | B3: N-OPEN RG NATURAL 64C (L-F)-ET | C3: 50081409 | D3: N-OPEN RG NATURAL 64C (L-F)-NS | E3: 50082198 | F3: LDPE: RELENE 22FF002 | G3: 0.597 | L3: 50081417 | M3: N-OPEN NS DTUBE NAT. ASSY -NS | N3: 50081954 | O3: N-NASAL SPRAY OPEN NATURAL (L) | U3: 50081429 | V3: CR-38MM VIOLET .035FSM-1 BLK | W3: 50082144 | X3: 38MM INNER CAPS NATURAL | Y3: =VLOOKUP(W3,Sheet2!A:D,3,0) -> 50082181 | Z3: =VLOOKUP(W3,Sheet2!A:D,4,0) -> PPHP: COPYLENE CH120LN
A4: 50081413 | B4: N-OPEN RG NATURAL 32C(L-F) -GS | C4: 50081412 | D4: N-OPEN RG NATURAL 32C(L-F) -NS | E4: 50082198 | F4: LDPE: RELENE 22FF002 | G4: 0.566 | L4: 50081419 | M4: N-NBSR ASSY WHITE(1005FY20)-NS | N4: 50081596 | O4: N-OPEN NBSR WHITE(1005FY20) | U4: 50081430 | V4: CR-38MM HS225 TG II PLAIN | W4: 50082144 | X4: 38MM INNER CAPS NATURAL | Y4: =VLOOKUP(W4,Sheet2!A:D,3,0) -> 50082181 | Z4: =VLOOKUP(W4,Sheet2!A:D,4,0) -> PPHP: COPYLENE CH120LN
A5: 50081414 | B5: N-OPEN RG NATURAL 32C(L-F) -ET | C5: 50081412 | D5: N-OPEN RG NATURAL 32C(L-F) -NS | E5: 50082198 | F5: LDPE: RELENE 22FF002 | G5: 0.566 | L5: 50081429 | M5: CR-38MM VIOLET .035FSM-1 BLK | N5: 50081994 | O5: 38MM OUTER CAPS VIOLET (2612C) | U5: 50081430 | V5: CR-38MM HS225 TG II PLAIN | W5: 50082177 | X5: 38MM OUTER CAPS WHITE | Y5: =VLOOKUP(W5,Sheet2!A:D,3,0) -> 50082181 | Z5: =VLOOKUP(W5,Sheet2!A:D,4,0) -> PPHP: COPYLENE CH120LN
A6: 50081462 | B6: B-5ML EX. RG WHITE (L-F)-GS | C6: 50081461 | D6: B-5ML EX. RG WHITE (L-F)-NS | E6: 50082198 | F6: LDPE: RELENE 22FF002 | G6: 2.8812 | H6: 50082194 | I6: MB: REMAFIN WHITE P7 | J6: 0.0588 | L6: 50081429 | M6: CR-38MM VIOLET .035FSM-1 BLK | N6: 50082144 | O6: 38MM INNER CAPS NATURAL | U6: 50081431 | V6: CR-38MM BLUE2945CHS130/020 BLK | W6: 50081995 | X6: 38MM OUTER CAPS BLUE (2945C) | Y6: =VLOOKUP(W6,Sheet2!A:D,3,0) -> 50082181 | Z6: =VLOOKUP(W6,Sheet2!A:D,4,0) -> PPHP: COPYLENE CH120LN
A7: 50081463 | B7: B-5ML EX. RG WHITE (L-F)-ET | C7: 50081461 | D7: B-5ML EX. RG WHITE (L-F)-NS | E7: 50082198 | F7: LDPE: RELENE 22FF002 | G7: 2.8812 | H7: 50082194 | I7: MB: REMAFIN WHITE P7 | J7: 0.0588 | L7: 50081430 | M7: CR-38MM HS225 TG II PLAIN | N7: 50082144 | O7: 38MM INNER CAPS NATURAL | U7: 50081431 | V7: CR-38MM BLUE2945CHS130/020 BLK | W7: 50082144 | X7: 38MM INNER CAPS NATURAL | Y7: =VLOOKUP(W7,Sheet2!A:D,3,0) -> 50082181 | Z7: =VLOOKUP(W7,Sheet2!A:D,4,0) -> PPHP: COPYLENE CH120LN
A8: 50081469 | B8: B-10ML RG WHITE 16C (L-F)-GS | C8: 50081468 | D8: B-10ML RG WHITE 16C (L-F)-NS | E8: 50082198 | F8: LDPE: RELENE 22FF002 | G8: 3.5486 | H8: 50082194 | I8: MB: REMAFIN WHITE P7 | J8: 0.0724 | L8: 50081430 | M8: CR-38MM HS225 TG II PLAIN | N8: 50082177 | O8: 38MM OUTER CAPS WHITE | U8: 50081432 | V8: CR-38MM BEIGE .035 SG100 PLAIN | W8: 50081702 | X8: 38MM OUTER CAPS BEIGE(AMPACET) | Y8: =VLOOKUP(W8,Sheet2!A:D,3,0) -> 50082181 | Z8: =VLOOKUP(W8,Sheet2!A:D,4,0) -> PPHP: COPYLENE CH120LN
A9: 50081472 | B9: B-10ML EX. RG WHITE (L-F)-GS | C9: 50081474 | D9: B-10ML EX. RG WHITE (L-F)-NS | E9: 50082198 | F9: LDPE: RELENE 22FF002 | G9: 3.459 | H9: 50082194 | I9: MB: REMAFIN WHITE P7 | J9: 0.0706 | L9: 50081431 | M9: CR-38MM BLUE2945CHS130/020 BLK | N9: 50081995 | O9: 38MM OUTER CAPS BLUE (2945C) | U9: 50081432 | V9: CR-38MM BEIGE .035 SG100 PLAIN | W9: 50082144 | X9: 38MM INNER CAPS NATURAL | Y9: =VLOOKUP(W9,Sheet2!A:D,3,0) -> 50082181 | Z9: =VLOOKUP(W9,Sheet2!A:D,4,0) -> PPHP: COPYLENE CH120LN
A10: 50081473 | B10: B-10ML EX. RG WHITE (L-F)-ET | C10: 50081474 | D10: B-10ML EX. RG WHITE (L-F)-NS | E10: 50082198 | F10: LDPE: RELENE 22FF002 | G10: 3.459 | H10: 50082194 | I10: MB: REMAFIN WHITE P7 | J10: 0.0706 | L10: 50081431 | M10: CR-38MM BLUE2945CHS130/020 BLK | N10: 50082144 | O10: 38MM INNER CAPS NATURAL | U10: 50081433 | V10: CR-33MM-PIC HS035/.025WLP RED | W10: 50081832 | X10: 33MM OUTER CAPS WHITE PIC | Y10: =VLOOKUP(W10,Sheet2!A:D,3,0) -> 50082181 | Z10: =VLOOKUP(W10,Sheet2!A:D,4,0) -> PPHP: COPYLENE CH120LN
A11: 50081532 | B11: B-5ML RG WHITE (L-F) DS-ET | C11: 50081531 | D11: B-5ML RG WHITE (L-F) DS-NS | E11: 50082198 | F11: LDPE: RELENE 22FF002 | G11: 2.842 | H11: 50082194 | I11: MB: REMAFIN WHITE P7 | J11: 0.058 | L11: 50081432 | M11: CR-38MM BEIGE .035 SG100 PLAIN | N11: 50081702 | O11: 38MM OUTER CAPS BEIGE(AMPACET) | U11: 50081433 | V11: CR-33MM-PIC HS035/.025WLP RED | W11: 50082145 | X11: 33MM INNER CAPS NATURAL | Y11: =VLOOKUP(W11,Sheet2!A:D,3,0) -> 50082181 | Z11: =VLOOKUP(W11,Sheet2!A:D,4,0) -> PPHP: COPYLENE CH120LN
A12: 50081552 | B12: N-BLOCK RG NATURAL (L-F)-GS | C12: 50081489 | D12: N-BLOCK RG NATURAL (L-F)-NS | E12: 50082198 | F12: LDPE: RELENE 22FF002 | G12: 0.62 | L12: 50081432 | M12: CR-38MM BEIGE .035 SG100 PLAIN | N12: 50082144 | O12: 38MM INNER CAPS NATURAL | U12: 50081434 | V12: CR-33MM(RL) HS123/0.020 WHITE | W12: 50081590 | X12: 33MM INNER CAPS NAT.(H110MA) | Y12: =VLOOKUP(W12,Sheet2!A:D,3,0) -> 50082203 | Z12: =VLOOKUP(W12,Sheet2!A:D,4,0) -> PPHP: REPOL H110MA
A13: 50081553 | B13: N-BLOCK RG NATURAL (L-F)-ET | C13: 50081489 | D13: N-BLOCK RG NATURAL (L-F)-NS | E13: 50082198 | F13: LDPE: RELENE 22FF002 | G13: 0.62 | L13: 50081433 | M13: CR-33MM-PIC HS035/.025WLP RED | N13: 50081832 | O13: 33MM OUTER CAPS WHITE PIC | U13: 50081434 | V13: CR-33MM(RL) HS123/0.020 WHITE | W13: 50081703 | X13: 33MM OUTER WHITE CAPS (H110MA) | Y13: =VLOOKUP(W13,Sheet2!A:D,3,0) -> 50082203 | Z13: =VLOOKUP(W13,Sheet2!A:D,4,0) -> PPHP: REPOL H110MA
A14: 50081576 | B14: B-5ML RG WHITE (L-F) DS-GS | C14: 50081531 | D14: B-5ML RG WHITE (L-F) DS-NS | E14: 50082198 | F14: LDPE: RELENE 22FF002 | G14: 2.842 | H14: 50082194 | I14: MB: REMAFIN WHITE P7 | J14: 0.058 | L14: 50081433 | M14: CR-33MM-PIC HS035/.025WLP RED | N14: 50082145 | O14: 33MM INNER CAPS NATURAL | U14: 50081435 | V14: CR-33MM HS130/.020 BLK | W14: 50082145 | X14: 33MM INNER CAPS NATURAL | Y14: =VLOOKUP(W14,Sheet2!A:D,3,0) -> 50082181 | Z14: =VLOOKUP(W14,Sheet2!A:D,4,0) -> PPHP: COPYLENE CH120LN
A15: 50081581 | B15: B-15ML RG WHITE (L-F)-GS | C15: 50081580 | D15: B-15ML RG WHITE (L-F)-NS | E15: 50082198 | F15: LDPE: RELENE 22FF002 | G15: 4.41 | H15: 50082194 | I15: MB: REMAFIN WHITE P7 | J15: 0.09 | L15: 50081434 | M15: CR-33MM(RL) HS123/0.020 WHITE | N15: 50081590 | O15: 33MM INNER CAPS NAT.(H110MA) | U15: 50081435 | V15: CR-33MM HS130/.020 BLK | W15: 50082178 | X15: 33MM OUTER CAPS WHITE | Y15: =VLOOKUP(W15,Sheet2!A:D,3,0) -> 50082181 | Z15: =VLOOKUP(W15,Sheet2!A:D,4,0) -> PPHP: COPYLENE CH120LN
A16: 50081582 | B16: B-15ML RG WHITE (L-F)-ET | C16: 50081580 | D16: B-15ML RG WHITE (L-F)-NS | E16: 50082198 | F16: LDPE: RELENE 22FF002 | G16: 4.41 | H16: 50082194 | I16: MB: REMAFIN WHITE P7 | J16: 0.09 | L16: 50081434 | M16: CR-33MM(RL) HS123/0.020 WHITE | N16: 50081703 | O16: 33MM OUTER WHITE CAPS (H110MA) | U16: 50081436 | V16: CR-33MM HS130/035WLP BLK | W16: 50082145 | X16: 33MM INNER CAPS NATURAL | Y16: =VLOOKUP(W16,Sheet2!A:D,3,0) -> 50082181 | Z16: =VLOOKUP(W16,Sheet2!A:D,4,0) -> PPHP: COPYLENE CH120LN
A17: 50081594 | B17: N-OPEN RG NAT. NEW(1840H)-GS | C17: 50081593 | D17: N-OPEN RG NAT. NEW(1840H)-NS | E17: 50082183 | F17: LDPE: PURELL PE 1840 H | G17: 0.602 | L17: 50081435 | M17: CR-33MM HS130/.020 BLK | N17: 50082145 | O17: 33MM INNER CAPS NATURAL | U17: 50081436 | V17: CR-33MM HS130/035WLP BLK | W17: 50082178 | X17: 33MM OUTER CAPS WHITE | Y17: =VLOOKUP(W17,Sheet2!A:D,3,0) -> 50082181 | Z17: =VLOOKUP(W17,Sheet2!A:D,4,0) -> PPHP: COPYLENE CH120LN
A18: 50081595 | B18: N-OPEN RG NAT. NEW(1840H)-ET | C18: 50081593 | D18: N-OPEN RG NAT. NEW(1840H)-NS | E18: 50082183 | F18: LDPE: PURELL PE 1840 H | G18: 0.602 | L18: 50081435 | M18: CR-33MM HS130/.020 BLK | N18: 50082178 | O18: 33MM OUTER CAPS WHITE | U18: 50081437 | V18: CR-33MM VIOLET .035 FSM-1 BLK | W18: 50081996 | X18: 33MM OUTER CAPS VIOLET(2612C) | Y18: =VLOOKUP(W18,Sheet2!A:D,3,0) -> 50082181 | Z18: =VLOOKUP(W18,Sheet2!A:D,4,0) -> PPHP: COPYLENE CH120LN
A19: 50081636 | B19: B-5ML RG WHITE (L-1840H)-GS | C19: 50081635 | D19: B-5ML RG WHITE (L-1840H)-NS | E19: 50082183 | F19: LDPE: PURELL PE 1840 H | G19: 2.842 | H19: 50082194 | I19: MB: REMAFIN WHITE P7 | J19: 0.058 | L19: 50081436 | M19: CR-33MM HS130/035WLP BLK | N19: 50082145 | O19: 33MM INNER CAPS NATURAL | U19: 50081437 | V19: CR-33MM VIOLET .035 FSM-1 BLK | W19: 50082145 | X19: 33MM INNER CAPS NATURAL | Y19: =VLOOKUP(W19,Sheet2!A:D,3,0) -> 50082181 | Z19: =VLOOKUP(W19,Sheet2!A:D,4,0) -> PPHP: COPYLENE CH120LN
A20: 50081637 | B20: B-5ML RG WHITE (L-1840H)-ET | C20: 50081635 | D20: B-5ML RG WHITE (L-1840H)-NS | E20: 50082183 | F20: LDPE: PURELL PE 1840 H | G20: 2.842 | H20: 50082194 | I20: MB: REMAFIN WHITE P7 | J20: 0.058 | L20: 50081436 | M20: CR-33MM HS130/035WLP BLK | N20: 50082178 | O20: 33MM OUTER CAPS WHITE | U20: 50081438 | V20: CR-33MM HS035 PL /.025"WLP RED | W20: 50082145 | X20: 33MM INNER CAPS NATURAL | Y20: =VLOOKUP(W20,Sheet2!A:D,3,0) -> 50082181 | Z20: =VLOOKUP(W20,Sheet2!A:D,4,0) -> PPHP: COPYLENE CH120LN
A21: 50081642 | B21: B-10ML RG WHITE (L-F)-GS | C21: 50081641 | D21: B-10ML RG WHITE (L-F)-NS | E21: 50082198 | F21: LDPE: RELENE 22FF002 | G21: 3.5486 | H21: 50082194 | I21: MB: REMAFIN WHITE P7 | J21: 0.0724 | L21: 50081437 | M21: CR-33MM VIOLET .035 FSM-1 BLK | N21: 50081996 | O21: 33MM OUTER CAPS VIOLET(2612C) | U21: 50081438 | V21: CR-33MM HS035 PL /.025"WLP RED | W21: 50082178 | X21: 33MM OUTER CAPS WHITE | Y21: =VLOOKUP(W21,Sheet2!A:D,3,0) -> 50082181 | Z21: =VLOOKUP(W21,Sheet2!A:D,4,0) -> PPHP: COPYLENE CH120LN
A22: 50081717 | B22: N-OPEN RG NATURAL (L-1840H)-GS | C22: 50081716 | D22: N-OPEN RG NATURAL (L-1840H)-NS | E22: 50082183 | F22: LDPE: PURELL PE 1840 H | G22: 0.56 | L22: 50081437 | M22: CR-33MM VIOLET .035 FSM-1 BLK | N22: 50082145 | O22: 33MM INNER CAPS NATURAL | U22: 50081439 | V22: CR-33MM BLUE2945C HS130/020BLK | W22: 50081997 | X22: 33MM OUTER CAPS BLUE (2945C) | Y22: =VLOOKUP(W22,Sheet2!A:D,3,0) -> 50082181 | Z22: =VLOOKUP(W22,Sheet2!A:D,4,0) -> PPHP: COPYLENE CH120LN
A23: 50081718 | B23: N-OPEN RG NATURAL (L-1840H)-ET | C23: 50081716 | D23: N-OPEN RG NATURAL (L-1840H)-NS | E23: 50082183 | F23: LDPE: PURELL PE 1840 H | G23: 0.56 | L23: 50081438 | M23: CR-33MM HS035 PL /.025"WLP RED | N23: 50082145 | O23: 33MM INNER CAPS NATURAL | U23: 50081439 | V23: CR-33MM BLUE2945C HS130/020BLK | W23: 50082145 | X23: 33MM INNER CAPS NATURAL | Y23: =VLOOKUP(W23,Sheet2!A:D,3,0) -> 50082181 | Z23: =VLOOKUP(W23,Sheet2!A:D,4,0) -> PPHP: COPYLENE CH120LN
A24: 50081746 | B24: N-BLOCK RG WHITE (L-F)-GS | C24: 50081719 | D24: N-BLOCK RG WHITE (L-F)-NS | E24: 50082198 | F24: LDPE: RELENE 22FF002 | G24: 0.588 | H24: 50082194 | I24: MB: REMAFIN WHITE P7 | J24: 0.012 | L24: 50081438 | M24: CR-33MM HS035 PL /.025"WLP RED | N24: 50082178 | O24: 33MM OUTER CAPS WHITE | U24: 50081440 | V24: CR-28MM-030 FSE7-6S BLK | W24: 50082179 | X24: 28MM OUTER CAPS WHITE | Y24: =VLOOKUP(W24,Sheet2!A:D,3,0) -> 50082181 | Z24: =VLOOKUP(W24,Sheet2!A:D,4,0) -> PPHP: COPYLENE CH120LN
A25: 50081786 | B25: B-5ML EX.RG O.GREEN (L)-GS | C25: 50081785 | D25: B-5ML EX.RG O.GREEN (L)-NS | E25: 50082184 | F25: LDPE: PURELL PE 1810 E | G25: 2.8714 | H25: 50082152 | I25: MB:REMAFIN GREEN 91151 | J25: 0.0586 | L25: 50081439 | M25: CR-33MM BLUE2945C HS130/020BLK | N25: 50081997 | O25: 33MM OUTER CAPS BLUE (2945C) | U25: 50081440 | V25: CR-28MM-030 FSE7-6S BLK | W25: 50082180 | X25: 28MM INNER CAPS NATURAL | Y25: =VLOOKUP(W25,Sheet2!A:D,3,0) -> 50082181 | Z25: =VLOOKUP(W25,Sheet2!A:D,4,0) -> PPHP: COPYLENE CH120LN
A26: 50081787 | B26: B-5ML EX.RG O.GREEN (L)-ET | C26: 50081785 | D26: B-5ML EX.RG O.GREEN (L)-NS | E26: 50082184 | F26: LDPE: PURELL PE 1810 E | G26: 2.8714 | H26: 50082152 | I26: MB:REMAFIN GREEN 91151 | J26: 0.0586 | L26: 50081439 | M26: CR-33MM BLUE2945C HS130/020BLK | N26: 50082145 | O26: 33MM INNER CAPS NATURAL | U26: 50081441 | V26: CR-28MM HS130/.020 WLP BLK | W26: 50082179 | X26: 28MM OUTER CAPS WHITE | Y26: =VLOOKUP(W26,Sheet2!A:D,3,0) -> 50082181 | Z26: =VLOOKUP(W26,Sheet2!A:D,4,0) -> PPHP: COPYLENE CH120LN
A27: 50081789 | B27: B-10ML EX.RG O.GREEN (L)-GS | C27: 50081788 | D27: B-10ML EX.RG O.GREEN (L)-NS | E27: 50082184 | F27: LDPE: PURELL PE 1810 E | G27: 3.4374 | H27: 50082152 | I27: MB:REMAFIN GREEN 91151 | J27: 0.0702 | L27: 50081440 | M27: CR-28MM-030 FSE7-6S BLK | N27: 50082179 | O27: 28MM OUTER CAPS WHITE | U27: 50081441 | V27: CR-28MM HS130/.020 WLP BLK | W27: 50082180 | X27: 28MM INNER CAPS NATURAL | Y27: =VLOOKUP(W27,Sheet2!A:D,3,0) -> 50082181 | Z27: =VLOOKUP(W27,Sheet2!A:D,4,0) -> PPHP: COPYLENE CH120LN
A28: 50081790 | B28: B-10ML EX.RG O.GREEN (L)-ET | C28: 50081788 | D28: B-10ML EX.RG O.GREEN (L)-NS | E28: 50082184 | F28: LDPE: PURELL PE 1810 E | G28: 3.4374 | H28: 50082152 | I28: MB:REMAFIN GREEN 91151 | J28: 0.0702 | L28: 50081440 | M28: CR-28MM-030 FSE7-6S BLK | N28: 50082180 | O28: 28MM INNER CAPS NATURAL | U28: 50081442 | V28: CR-28MM .035 FSLE 1-13 BLK | W28: 50082179 | X28: 28MM OUTER CAPS WHITE | Y28: =VLOOKUP(W28,Sheet2!A:D,3,0) -> 50082181 | Z28: =VLOOKUP(W28,Sheet2!A:D,4,0) -> PPHP: COPYLENE CH120LN
A29: 50081792 | B29: B-10ML EX. RG NATURAL (L)-GS | C29: 50081791 | D29: B-10ML EX. RG NATURAL (L)-NS | E29: 50082184 | F29: LDPE: PURELL PE 1810 E | G29: 3.4625 | L29: 50081441 | M29: CR-28MM HS130/.020 WLP BLK | N29: 50082179 | O29: 28MM OUTER CAPS WHITE | U29: 50081442 | V29: CR-28MM .035 FSLE 1-13 BLK | W29: 50082180 | X29: 28MM INNER CAPS NATURAL | Y29: =VLOOKUP(W29,Sheet2!A:D,3,0) -> 50082181 | Z29: =VLOOKUP(W29,Sheet2!A:D,4,0) -> PPHP: COPYLENE CH120LN
A30: 50081793 | B30: B-10ML EX. RG NATURAL (L)-ET | C30: 50081791 | D30: B-10ML EX. RG NATURAL (L)-NS | E30: 50082184 | F30: LDPE: PURELL PE 1810 E | G30: 3.4625 | L30: 50081441 | M30: CR-28MM HS130/.020 WLP BLK | N30: 50082180 | O30: 28MM INNER CAPS NATURAL | U30: 50081443 | V30: CR-28MM - 020 CCFWR FSE1-15 | W30: 50082179 | X30: 28MM OUTER CAPS WHITE | Y30: =VLOOKUP(W30,Sheet2!A:D,3,0) -> 50082181 | Z30: =VLOOKUP(W30,Sheet2!A:D,4,0) -> PPHP: COPYLENE CH120LN
A31: 50081825 | B31: B-30ML RG NBSR WHITE (L)-GS | C31: 50081824 | D31: B-30ML RG NBSR WHITE (L)-NS | E31: 50082183 | F31: LDPE: PURELL PE 1840 H | G31: 6.4329 | H31: 50081420 | I31: MB: MELCOMAITRE WHT08636 1840H | J31: 0.4106 | L31: 50081442 | M31: CR-28MM .035 FSLE 1-13 BLK | N31: 50082179 | O31: 28MM OUTER CAPS WHITE | U31: 50081443 | V31: CR-28MM - 020 CCFWR FSE1-15 | W31: 50082180 | X31: 28MM INNER CAPS NATURAL | Y31: =VLOOKUP(W31,Sheet2!A:D,3,0) -> 50082181 | Z31: =VLOOKUP(W31,Sheet2!A:D,4,0) -> PPHP: COPYLENE CH120LN
A32: 50081826 | B32: B-30ML RG NBSR WHITE (L)-ET | C32: 50081824 | D32: B-30ML RG NBSR WHITE (L)-NS | E32: 50082183 | F32: LDPE: PURELL PE 1840 H | G32: 6.4329 | H32: 50081420 | I32: MB: MELCOMAITRE WHT08636 1840H | J32: 0.4106 | L32: 50081442 | M32: CR-28MM .035 FSLE 1-13 BLK | N32: 50082180 | O32: 28MM INNER CAPS NATURAL | U32: 50081444 | V32: CR-38MM -035 WLPM FSM -1 BLK | W32: 50082144 | X32: 38MM INNER CAPS NATURAL | Y32: =VLOOKUP(W32,Sheet2!A:D,3,0) -> 50082181 | Z32: =VLOOKUP(W32,Sheet2!A:D,4,0) -> PPHP: COPYLENE CH120LN
A33: 50081828 | B33: B-15ML EX.RG WHITE (L)-GS | C33: 50081827 | D33: B-15ML EX.RG WHITE (L)-NS | E33: 50082184 | F33: LDPE: PURELL PE 1810 E | G33: 4.41 | H33: 50082194 | I33: MB: REMAFIN WHITE P7 | J33: 0.09 | L33: 50081443 | M33: CR-28MM - 020 CCFWR FSE1-15 | N33: 50082179 | O33: 28MM OUTER CAPS WHITE | U33: 50081444 | V33: CR-38MM -035 WLPM FSM -1 BLK | W33: 50082177 | X33: 38MM OUTER CAPS WHITE | Y33: =VLOOKUP(W33,Sheet2!A:D,3,0) -> 50082181 | Z33: =VLOOKUP(W33,Sheet2!A:D,4,0) -> PPHP: COPYLENE CH120LN
A34: 50081829 | B34: B-15ML EX.RG WHITE (L)-ET | C34: 50081827 | D34: B-15ML EX.RG WHITE (L)-NS | E34: 50082184 | F34: LDPE: PURELL PE 1810 E | G34: 4.41 | H34: 50082194 | I34: MB: REMAFIN WHITE P7 | J34: 0.09 | L34: 50081443 | M34: CR-28MM - 020 CCFWR FSE1-15 | N34: 50082180 | O34: 28MM INNER CAPS NATURAL | U34: 50081445 | V34: CR-38MM - HS 123 /035 WHITE | W34: 50082144 | X34: 38MM INNER CAPS NATURAL | Y34: =VLOOKUP(W34,Sheet2!A:D,3,0) -> 50082181 | Z34: =VLOOKUP(W34,Sheet2!A:D,4,0) -> PPHP: COPYLENE CH120LN
A35: 50081860 | B35: B-5ML RG O. GREEN (L) -GS | C35: 50081859 | D35: B-5ML RG O. GREEN (L) -NS | E35: 50082184 | F35: LDPE: PURELL PE 1810 E | G35: 2.8812 | H35: 50082152 | I35: MB:REMAFIN GREEN 91151 | J35: 0.0588 | L35: 50081444 | M35: CR-38MM -035 WLPM FSM -1 BLK | N35: 50082144 | O35: 38MM INNER CAPS NATURAL | U35: 50081445 | V35: CR-38MM - HS 123 /035 WHITE | W35: 50082177 | X35: 38MM OUTER CAPS WHITE | Y35: =VLOOKUP(W35,Sheet2!A:D,3,0) -> 50082181 | Z35: =VLOOKUP(W35,Sheet2!A:D,4,0) -> PPHP: COPYLENE CH120LN
A36: 50081861 | B36: B-5ML RG O. GREEN (L) -ET | C36: 50081859 | D36: B-5ML RG O. GREEN (L) -NS | E36: 50082184 | F36: LDPE: PURELL PE 1810 E | G36: 2.8812 | H36: 50082152 | I36: MB:REMAFIN GREEN 91151 | J36: 0.0588 | L36: 50081444 | M36: CR-38MM -035 WLPM FSM -1 BLK | N36: 50082177 | O36: 38MM OUTER CAPS WHITE | U36: 50081446 | V36: CR-38MM - HS 123 /020 WHITE | W36: 50082144 | X36: 38MM INNER CAPS NATURAL | Y36: =VLOOKUP(W36,Sheet2!A:D,3,0) -> 50082181 | Z36: =VLOOKUP(W36,Sheet2!A:D,4,0) -> PPHP: COPYLENE CH120LN
A37: 50081866 | B37: B-5ML EX. RG WHITE (L)-GS | C37: 50081865 | D37: B-5ML EX. RG WHITE (L)-NS | E37: 50082184 | F37: LDPE: PURELL PE 1810 E | G37: 2.842 | H37: 50082194 | I37: MB: REMAFIN WHITE P7 | J37: 0.058 | L37: 50081445 | M37: CR-38MM - HS 123 /035 WHITE | N37: 50082144 | O37: 38MM INNER CAPS NATURAL | U37: 50081446 | V37: CR-38MM - HS 123 /020 WHITE | W37: 50082177 | X37: 38MM OUTER CAPS WHITE | Y37: =VLOOKUP(W37,Sheet2!A:D,3,0) -> 50082181 | Z37: =VLOOKUP(W37,Sheet2!A:D,4,0) -> PPHP: COPYLENE CH120LN
A38: 50081867 | B38: B-5ML EX. RG WHITE (L)-ET | C38: 50081865 | D38: B-5ML EX. RG WHITE (L)-NS | E38: 50082184 | F38: LDPE: PURELL PE 1810 E | G38: 2.842 | H38: 50082194 | I38: MB: REMAFIN WHITE P7 | J38: 0.058 | L38: 50081445 | M38: CR-38MM - HS 123 /035 WHITE | N38: 50082177 | O38: 38MM OUTER CAPS WHITE | U38: 50081447 | V38: CR-33MM HS035/35 WLP RED | W38: 50082145 | X38: 33MM INNER CAPS NATURAL | Y38: =VLOOKUP(W38,Sheet2!A:D,3,0) -> 50082181 | Z38: =VLOOKUP(W38,Sheet2!A:D,4,0) -> PPHP: COPYLENE CH120LN
A39: 50081873 | B39: B-15ML RG WHITE (L-1840H)-GS | C39: 50081872 | D39: B-15ML RG WHITE (L-1840H)-NS | E39: 50082183 | F39: LDPE: PURELL PE 1840 H | G39: 4.3865 | H39: 50082194 | I39: MB: REMAFIN WHITE P7 | J39: 0.0895 | L39: 50081446 | M39: CR-38MM - HS 123 /020 WHITE | N39: 50082144 | O39: 38MM INNER CAPS NATURAL | U39: 50081447 | V39: CR-33MM HS035/35 WLP RED | W39: 50082178 | X39: 33MM OUTER CAPS WHITE | Y39: =VLOOKUP(W39,Sheet2!A:D,3,0) -> 50082181 | Z39: =VLOOKUP(W39,Sheet2!A:D,4,0) -> PPHP: COPYLENE CH120LN
A40: 50081874 | B40: B-15ML RG WHITE (L-1840H)-ET | C40: 50081872 | D40: B-15ML RG WHITE (L-1840H)-NS | E40: 50082183 | F40: LDPE: PURELL PE 1840 H | G40: 4.3865 | H40: 50082194 | I40: MB: REMAFIN WHITE P7 | J40: 0.0895 | L40: 50081446 | M40: CR-38MM - HS 123 /020 WHITE | N40: 50082177 | O40: 38MM OUTER CAPS WHITE | U40: 50081448 | V40: CR-33MM 035 WLPM FSM -1 BLK | W40: 50082145 | X40: 33MM INNER CAPS NATURAL | Y40: =VLOOKUP(W40,Sheet2!A:D,3,0) -> 50082181 | Z40: =VLOOKUP(W40,Sheet2!A:D,4,0) -> PPHP: COPYLENE CH120LN
...

Sheet Sheet2
A1: Material Code | B1: Material Description | C1: Component Item Number | D1: Material Description2 | F1: Material Code | G1: Material Description | H1: WEIGHT
A2: 50081590 | B2: 33MM INNER CAPS NAT.(H110MA) | C2: 50082203 | D2: PPHP: REPOL H110MA | F2: 50081590 | G2: 33MM INNER CAPS NAT.(H110MA) | H2: 3
A3: 50081651 | B3: 33MMPIC OUTERCAPS BLUE466276 | C3: 50082181 | D3: PPHP: COPYLENE CH120LN | F3: 50081651 | G3: 33MMPIC OUTERCAPS BLUE466276 | H3: 3.589
A4: 50081702 | B4: 38MM OUTER CAPS BEIGE(AMPACET) | C4: 50082181 | D4: PPHP: COPYLENE CH120LN | F4: 50081702 | G4: 38MM OUTER CAPS BEIGE(AMPACET) | H4: 3.977
A5: 50081703 | B5: 33MM OUTER WHITE CAPS (H110MA) | C5: 50082203 | D5: PPHP: REPOL H110MA | F5: 50081703 | G5: 33MM OUTER WHITE CAPS (H110MA) | H5: 3.8897
A6: 50081704 | B6: 33MM OUTER CAPS MEVO L. GREEN | C6: 50082181 | D6: PPHP: COPYLENE CH120LN | F6: 50081704 | G6: 33MM OUTER CAPS MEVO L. GREEN | H6: 3.456
A7: 50081832 | B7: 33MM OUTER CAPS WHITE PIC | C7: 50082181 | D7: PPHP: COPYLENE CH120LN | F7: 50081832 | G7: 33MM OUTER CAPS WHITE PIC | H7: 3.589
A8: 50081887 | B8: 38MM INNER CAPS NAT.(H110MA) | C8: 50082203 | D8: PPHP: REPOL H110MA | F8: 50081887 | G8: 38MM INNER CAPS NAT.(H110MA) | H8: 3.7
A9: 50081993 | B9: 38MM OUTER CAPS WHITE(H110MA) | C9: 50082203 | D9: PPHP: REPOL H110MA | F9: 50081993 | G9: 38MM OUTER CAPS WHITE(H110MA) | H9: 3.977
A10: 50081994 | B10: 38MM OUTER CAPS VIOLET (2612C) | C10: 50082181 | D10: PPHP: COPYLENE CH120LN | F10: 50081994 | G10: 38MM OUTER CAPS VIOLET (2612C) | H10: 3.977
A11: 50081995 | B11: 38MM OUTER CAPS BLUE (2945C) | C11: 50082181 | D11: PPHP: COPYLENE CH120LN | F11: 50081995 | G11: 38MM OUTER CAPS BLUE (2945C) | H11: 3.977
